[2025-01-08T05:42:40.069+0000] {local_task_job_runner.py:123} INFO - ::group::Pre task execution logs
[2025-01-08T05:42:40.097+0000] {taskinstance.py:2613} INFO - Dependencies all met for dep_context=non-requeueable deps ti=<TaskInstance: 1.5.0.trans_Referencesdata.transfer_data_task manual__2025-01-08T05:42:38.216079+00:00 [queued]>
[2025-01-08T05:42:40.113+0000] {taskinstance.py:2613} INFO - Dependencies all met for dep_context=requeueable deps ti=<TaskInstance: 1.5.0.trans_Referencesdata.transfer_data_task manual__2025-01-08T05:42:38.216079+00:00 [queued]>
[2025-01-08T05:42:40.113+0000] {taskinstance.py:2866} INFO - Starting attempt 1 of 2
[2025-01-08T05:42:40.133+0000] {taskinstance.py:2889} INFO - Executing <Task(PythonOperator): transfer_data_task> on 2025-01-08 05:42:38.216079+00:00
[2025-01-08T05:42:40.140+0000] {warnings.py:112} WARNING - /home/***/.local/lib/python3.12/site-packages/***/task/task_runner/standard_task_runner.py:70: DeprecationWarning: This process (pid=217) is multi-threaded, use of fork() may lead to deadlocks in the child.
  pid = os.fork()

[2025-01-08T05:42:40.142+0000] {standard_task_runner.py:72} INFO - Started process 218 to run task
[2025-01-08T05:42:40.142+0000] {standard_task_runner.py:104} INFO - Running: ['***', 'tasks', 'run', '1.5.0.trans_Referencesdata', 'transfer_data_task', 'manual__2025-01-08T05:42:38.216079+00:00', '--job-id', '17', '--raw', '--subdir', 'DAGS_FOLDER/TransactionService/1.5.initial_Transaction_Reference.py', '--cfg-path', '/tmp/tmp565blc9w']
[2025-01-08T05:42:40.144+0000] {standard_task_runner.py:105} INFO - Job 17: Subtask transfer_data_task
[2025-01-08T05:42:40.198+0000] {task_command.py:467} INFO - Running <TaskInstance: 1.5.0.trans_Referencesdata.transfer_data_task manual__2025-01-08T05:42:38.216079+00:00 [running]> on host 140af152fc10
[2025-01-08T05:42:40.376+0000] {taskinstance.py:3132} INFO - Exporting env vars: AIRFLOW_CTX_DAG_OWNER='***' AIRFLOW_CTX_DAG_ID='1.5.0.trans_Referencesdata' AIRFLOW_CTX_TASK_ID='transfer_data_task' AIRFLOW_CTX_EXECUTION_DATE='2025-01-08T05:42:38.216079+00:00' AIRFLOW_CTX_TRY_NUMBER='1' AIRFLOW_CTX_DAG_RUN_ID='manual__2025-01-08T05:42:38.216079+00:00'
[2025-01-08T05:42:40.379+0000] {taskinstance.py:731} INFO - ::endgroup::
[2025-01-08T05:42:40.442+0000] {base.py:84} INFO - Retrieving connection 'Transaction_db_connection'
[2025-01-08T05:42:42.549+0000] {logging_mixin.py:190} INFO - source_conn: connected to source db
[2025-01-08T05:42:42.558+0000] {base.py:84} INFO - Retrieving connection 'Report_db_connection'
[2025-01-08T05:42:42.624+0000] {logging_mixin.py:190} INFO - dest_conn: connected to destination db
[2025-01-08T05:42:42.839+0000] {logging_mixin.py:190} INFO - "code", "category", "name", "isdeleted", "configuration"
[2025-01-08T05:42:42.847+0000] {1.5.initial_Transaction_Reference.py:104} ERROR - Error in data transfer:
Traceback (most recent call last):
  File "/opt/airflow/dags/TransactionService/1.5.initial_Transaction_Reference.py", line 73, in transfer_data
    dest_cursor.execute(existing_id_query, (row[0],))
psycopg2.errors.UndefinedColumn: column "Code" does not exist
LINE 1: SELECT "Code" FROM "TransactionService_Reference" WHERE "Cod...
               ^
HINT:  Perhaps you meant to reference the column "TransactionService_Reference.code".

[2025-01-08T05:42:43.068+0000] {taskinstance.py:3311} ERROR - Task failed with exception
Traceback (most recent call last):
  File "/home/airflow/.local/lib/python3.12/site-packages/airflow/models/taskinstance.py", line 767, in _execute_task
    result = _execute_callable(context=context, **execute_callable_kwargs)
             ^^^^^^^^^^^^^^^^^^^^^^^^^^^^^^^^^^^^^^^^^^^^^^^^^^^^^^^^^^^^^
  File "/home/airflow/.local/lib/python3.12/site-packages/airflow/models/taskinstance.py", line 733, in _execute_callable
    return ExecutionCallableRunner(
           ^^^^^^^^^^^^^^^^^^^^^^^^
  File "/home/airflow/.local/lib/python3.12/site-packages/airflow/utils/operator_helpers.py", line 252, in run
    return self.func(*args, **kwargs)
           ^^^^^^^^^^^^^^^^^^^^^^^^^^
  File "/home/airflow/.local/lib/python3.12/site-packages/airflow/models/baseoperator.py", line 422, in wrapper
    return func(self, *args, **kwargs)
           ^^^^^^^^^^^^^^^^^^^^^^^^^^^
  File "/home/airflow/.local/lib/python3.12/site-packages/airflow/operators/python.py", line 238, in execute
    return_value = self.execute_callable()
                   ^^^^^^^^^^^^^^^^^^^^^^^
  File "/home/airflow/.local/lib/python3.12/site-packages/airflow/operators/python.py", line 256, in execute_callable
    return runner.run(*self.op_args, **self.op_kwargs)
           ^^^^^^^^^^^^^^^^^^^^^^^^^^^^^^^^^^^^^^^^^^^
  File "/home/airflow/.local/lib/python3.12/site-packages/airflow/utils/operator_helpers.py", line 252, in run
    return self.func(*args, **kwargs)
           ^^^^^^^^^^^^^^^^^^^^^^^^^^
  File "/opt/airflow/dags/TransactionService/1.5.initial_Transaction_Reference.py", line 73, in transfer_data
    dest_cursor.execute(existing_id_query, (row[0],))
psycopg2.errors.UndefinedColumn: column "Code" does not exist
LINE 1: SELECT "Code" FROM "TransactionService_Reference" WHERE "Cod...
               ^
HINT:  Perhaps you meant to reference the column "TransactionService_Reference.code".

[2025-01-08T05:42:43.091+0000] {taskinstance.py:1225} INFO - Marking task as UP_FOR_RETRY. dag_id=1.5.0.trans_Referencesdata, task_id=transfer_data_task, run_id=manual__2025-01-08T05:42:38.216079+00:00, execution_date=20250108T054238, start_date=20250108T054240, end_date=20250108T054243
[2025-01-08T05:42:43.120+0000] {taskinstance.py:340} INFO - ::group::Post task execution logs
[2025-01-08T05:42:43.121+0000] {standard_task_runner.py:124} ERROR - Failed to execute job 17 for task transfer_data_task (column "Code" does not exist
LINE 1: SELECT "Code" FROM "TransactionService_Reference" WHERE "Cod...
               ^
HINT:  Perhaps you meant to reference the column "TransactionService_Reference.code".
; 218)
Traceback (most recent call last):
  File "/home/airflow/.local/lib/python3.12/site-packages/airflow/task/task_runner/standard_task_runner.py", line 117, in _start_by_fork
    ret = args.func(args, dag=self.dag)
          ^^^^^^^^^^^^^^^^^^^^^^^^^^^^^
  File "/home/airflow/.local/lib/python3.12/site-packages/airflow/cli/cli_config.py", line 49, in command
    return func(*args, **kwargs)
           ^^^^^^^^^^^^^^^^^^^^^
  File "/home/airflow/.local/lib/python3.12/site-packages/airflow/utils/cli.py", line 116, in wrapper
    return f(*args, **kwargs)
           ^^^^^^^^^^^^^^^^^^
  File "/home/airflow/.local/lib/python3.12/site-packages/airflow/cli/commands/task_command.py", line 483, in task_run
    task_return_code = _run_task_by_selected_method(args, _dag, ti)
                       ^^^^^^^^^^^^^^^^^^^^^^^^^^^^^^^^^^^^^^^^^^^^
  File "/home/airflow/.local/lib/python3.12/site-packages/airflow/cli/commands/task_command.py", line 256, in _run_task_by_selected_method
    return _run_raw_task(args, ti)
           ^^^^^^^^^^^^^^^^^^^^^^^
  File "/home/airflow/.local/lib/python3.12/site-packages/airflow/cli/commands/task_command.py", line 341, in _run_raw_task
    return ti._run_raw_task(
           ^^^^^^^^^^^^^^^^^
  File "/home/airflow/.local/lib/python3.12/site-packages/airflow/utils/session.py", line 97, in wrapper
    return func(*args, session=session, **kwargs)
           ^^^^^^^^^^^^^^^^^^^^^^^^^^^^^^^^^^^^^^
  File "/home/airflow/.local/lib/python3.12/site-packages/airflow/models/taskinstance.py", line 3005, in _run_raw_task
    return _run_raw_task(
           ^^^^^^^^^^^^^^
  File "/home/airflow/.local/lib/python3.12/site-packages/airflow/models/taskinstance.py", line 273, in _run_raw_task
    TaskInstance._execute_task_with_callbacks(
  File "/home/airflow/.local/lib/python3.12/site-packages/airflow/models/taskinstance.py", line 3159, in _execute_task_with_callbacks
    result = self._execute_task(context, task_orig)
             ^^^^^^^^^^^^^^^^^^^^^^^^^^^^^^^^^^^^^^
  File "/home/airflow/.local/lib/python3.12/site-packages/airflow/models/taskinstance.py", line 3183, in _execute_task
    return _execute_task(self, context, task_orig)
           ^^^^^^^^^^^^^^^^^^^^^^^^^^^^^^^^^^^^^^^
  File "/home/airflow/.local/lib/python3.12/site-packages/airflow/models/taskinstance.py", line 767, in _execute_task
    result = _execute_callable(context=context, **execute_callable_kwargs)
             ^^^^^^^^^^^^^^^^^^^^^^^^^^^^^^^^^^^^^^^^^^^^^^^^^^^^^^^^^^^^^
  File "/home/airflow/.local/lib/python3.12/site-packages/airflow/models/taskinstance.py", line 733, in _execute_callable
    return ExecutionCallableRunner(
           ^^^^^^^^^^^^^^^^^^^^^^^^
  File "/home/airflow/.local/lib/python3.12/site-packages/airflow/utils/operator_helpers.py", line 252, in run
    return self.func(*args, **kwargs)
           ^^^^^^^^^^^^^^^^^^^^^^^^^^
  File "/home/airflow/.local/lib/python3.12/site-packages/airflow/models/baseoperator.py", line 422, in wrapper
    return func(self, *args, **kwargs)
           ^^^^^^^^^^^^^^^^^^^^^^^^^^^
  File "/home/airflow/.local/lib/python3.12/site-packages/airflow/operators/python.py", line 238, in execute
    return_value = self.execute_callable()
                   ^^^^^^^^^^^^^^^^^^^^^^^
  File "/home/airflow/.local/lib/python3.12/site-packages/airflow/operators/python.py", line 256, in execute_callable
    return runner.run(*self.op_args, **self.op_kwargs)
           ^^^^^^^^^^^^^^^^^^^^^^^^^^^^^^^^^^^^^^^^^^^
  File "/home/airflow/.local/lib/python3.12/site-packages/airflow/utils/operator_helpers.py", line 252, in run
    return self.func(*args, **kwargs)
           ^^^^^^^^^^^^^^^^^^^^^^^^^^
  File "/opt/airflow/dags/TransactionService/1.5.initial_Transaction_Reference.py", line 73, in transfer_data
    dest_cursor.execute(existing_id_query, (row[0],))
psycopg2.errors.UndefinedColumn: column "Code" does not exist
LINE 1: SELECT "Code" FROM "TransactionService_Reference" WHERE "Cod...
               ^
HINT:  Perhaps you meant to reference the column "TransactionService_Reference.code".

[2025-01-08T05:42:43.170+0000] {local_task_job_runner.py:266} INFO - Task exited with return code 1
[2025-01-08T05:42:43.196+0000] {taskinstance.py:3895} INFO - 0 downstream tasks scheduled from follow-on schedule check
[2025-01-08T05:42:43.199+0000] {local_task_job_runner.py:245} INFO - ::endgroup::
