[2025-02-10T04:56:30.524+0000] {local_task_job_runner.py:123} INFO - ::group::Pre task execution logs
[2025-02-10T04:56:30.555+0000] {taskinstance.py:2613} INFO - Dependencies all met for dep_context=non-requeueable deps ti=<TaskInstance: 1.11.0.trans_Bank.transfer_data_task manual__2025-02-10T04:56:27.737774+00:00 [queued]>
[2025-02-10T04:56:30.569+0000] {taskinstance.py:2613} INFO - Dependencies all met for dep_context=requeueable deps ti=<TaskInstance: 1.11.0.trans_Bank.transfer_data_task manual__2025-02-10T04:56:27.737774+00:00 [queued]>
[2025-02-10T04:56:30.570+0000] {taskinstance.py:2866} INFO - Starting attempt 1 of 2
[2025-02-10T04:56:30.591+0000] {taskinstance.py:2889} INFO - Executing <Task(PythonOperator): transfer_data_task> on 2025-02-10 04:56:27.737774+00:00
[2025-02-10T04:56:30.604+0000] {warnings.py:112} WARNING - /home/***/.local/lib/python3.12/site-packages/***/task/task_runner/standard_task_runner.py:70: DeprecationWarning: This process (pid=285) is multi-threaded, use of fork() may lead to deadlocks in the child.
  pid = os.fork()

[2025-02-10T04:56:30.607+0000] {standard_task_runner.py:104} INFO - Running: ['***', 'tasks', 'run', '1.11.0.trans_Bank', 'transfer_data_task', 'manual__2025-02-10T04:56:27.737774+00:00', '--job-id', '3', '--raw', '--subdir', 'DAGS_FOLDER/TransactionService/1.11.initial_Transaction_Bank.py', '--cfg-path', '/tmp/tmpikd5j5y8']
[2025-02-10T04:56:30.610+0000] {standard_task_runner.py:72} INFO - Started process 286 to run task
[2025-02-10T04:56:30.610+0000] {standard_task_runner.py:105} INFO - Job 3: Subtask transfer_data_task
[2025-02-10T04:56:30.691+0000] {task_command.py:467} INFO - Running <TaskInstance: 1.11.0.trans_Bank.transfer_data_task manual__2025-02-10T04:56:27.737774+00:00 [running]> on host f8e600115ac1
[2025-02-10T04:56:30.864+0000] {taskinstance.py:3132} INFO - Exporting env vars: AIRFLOW_CTX_DAG_OWNER='***' AIRFLOW_CTX_DAG_ID='1.11.0.trans_Bank' AIRFLOW_CTX_TASK_ID='transfer_data_task' AIRFLOW_CTX_EXECUTION_DATE='2025-02-10T04:56:27.737774+00:00' AIRFLOW_CTX_TRY_NUMBER='1' AIRFLOW_CTX_DAG_RUN_ID='manual__2025-02-10T04:56:27.737774+00:00'
[2025-02-10T04:56:30.867+0000] {taskinstance.py:731} INFO - ::endgroup::
[2025-02-10T04:56:31.003+0000] {base.py:84} INFO - Retrieving connection 'TransactionDB_MSSQL'
[2025-02-10T04:56:33.195+0000] {logging_mixin.py:190} INFO - source_conn: connected to source db
[2025-02-10T04:56:33.209+0000] {base.py:84} INFO - Retrieving connection 'ReportDB_Postgres'
[2025-02-10T04:56:34.264+0000] {1.11.initial_Transaction_Bank.py:104} ERROR - Error in data transfer:
Traceback (most recent call last):
  File "/opt/airflow/dags/TransactionService/1.11.initial_Transaction_Bank.py", line 46, in transfer_data
    dest_conn, dest_cursor, source_conn, source_cursor = get_db_connection()
                                                         ^^^^^^^^^^^^^^^^^^^
  File "/opt/airflow/dags/TransactionService/1.11.initial_Transaction_Bank.py", line 28, in get_db_connection
    dest_conn = get_Report_connection()
                ^^^^^^^^^^^^^^^^^^^^^^^
  File "/opt/airflow/dags/connection.py", line 25, in get_Report_connection
    return psycopg2.connect(conn_str)
           ^^^^^^^^^^^^^^^^^^^^^^^^^^
  File "/home/airflow/.local/lib/python3.12/site-packages/psycopg2/__init__.py", line 122, in connect
    conn = _connect(dsn, connection_factory=connection_factory, **kwasync)
           ^^^^^^^^^^^^^^^^^^^^^^^^^^^^^^^^^^^^^^^^^^^^^^^^^^^^^^^^^^^^^^^
psycopg2.OperationalError: connection to server at "10.2.28.190", port 5432 failed: FATAL:  database "Report" does not exist

[2025-02-10T04:56:34.275+0000] {taskinstance.py:3311} ERROR - Task failed with exception
Traceback (most recent call last):
  File "/opt/airflow/dags/TransactionService/1.11.initial_Transaction_Bank.py", line 46, in transfer_data
    dest_conn, dest_cursor, source_conn, source_cursor = get_db_connection()
                                                         ^^^^^^^^^^^^^^^^^^^
  File "/opt/airflow/dags/TransactionService/1.11.initial_Transaction_Bank.py", line 28, in get_db_connection
    dest_conn = get_Report_connection()
                ^^^^^^^^^^^^^^^^^^^^^^^
  File "/opt/airflow/dags/connection.py", line 25, in get_Report_connection
    return psycopg2.connect(conn_str)
           ^^^^^^^^^^^^^^^^^^^^^^^^^^
  File "/home/airflow/.local/lib/python3.12/site-packages/psycopg2/__init__.py", line 122, in connect
    conn = _connect(dsn, connection_factory=connection_factory, **kwasync)
           ^^^^^^^^^^^^^^^^^^^^^^^^^^^^^^^^^^^^^^^^^^^^^^^^^^^^^^^^^^^^^^^
psycopg2.OperationalError: connection to server at "10.2.28.190", port 5432 failed: FATAL:  database "Report" does not exist


During handling of the above exception, another exception occurred:

Traceback (most recent call last):
  File "/home/airflow/.local/lib/python3.12/site-packages/airflow/models/taskinstance.py", line 767, in _execute_task
    result = _execute_callable(context=context, **execute_callable_kwargs)
             ^^^^^^^^^^^^^^^^^^^^^^^^^^^^^^^^^^^^^^^^^^^^^^^^^^^^^^^^^^^^^
  File "/home/airflow/.local/lib/python3.12/site-packages/airflow/models/taskinstance.py", line 733, in _execute_callable
    return ExecutionCallableRunner(
           ^^^^^^^^^^^^^^^^^^^^^^^^
  File "/home/airflow/.local/lib/python3.12/site-packages/airflow/utils/operator_helpers.py", line 252, in run
    return self.func(*args, **kwargs)
           ^^^^^^^^^^^^^^^^^^^^^^^^^^
  File "/home/airflow/.local/lib/python3.12/site-packages/airflow/models/baseoperator.py", line 422, in wrapper
    return func(self, *args, **kwargs)
           ^^^^^^^^^^^^^^^^^^^^^^^^^^^
  File "/home/airflow/.local/lib/python3.12/site-packages/airflow/operators/python.py", line 238, in execute
    return_value = self.execute_callable()
                   ^^^^^^^^^^^^^^^^^^^^^^^
  File "/home/airflow/.local/lib/python3.12/site-packages/airflow/operators/python.py", line 256, in execute_callable
    return runner.run(*self.op_args, **self.op_kwargs)
           ^^^^^^^^^^^^^^^^^^^^^^^^^^^^^^^^^^^^^^^^^^^
  File "/home/airflow/.local/lib/python3.12/site-packages/airflow/utils/operator_helpers.py", line 252, in run
    return self.func(*args, **kwargs)
           ^^^^^^^^^^^^^^^^^^^^^^^^^^
  File "/opt/airflow/dags/TransactionService/1.11.initial_Transaction_Bank.py", line 107, in transfer_data
    source_cursor.close()
    ^^^^^^^^^^^^^
UnboundLocalError: cannot access local variable 'source_cursor' where it is not associated with a value
[2025-02-10T04:56:34.298+0000] {taskinstance.py:1225} INFO - Marking task as UP_FOR_RETRY. dag_id=1.11.0.trans_Bank, task_id=transfer_data_task, run_id=manual__2025-02-10T04:56:27.737774+00:00, execution_date=20250210T045627, start_date=20250210T045630, end_date=20250210T045634
[2025-02-10T04:56:34.321+0000] {taskinstance.py:340} INFO - ::group::Post task execution logs
[2025-02-10T04:56:34.322+0000] {standard_task_runner.py:124} ERROR - Failed to execute job 3 for task transfer_data_task (cannot access local variable 'source_cursor' where it is not associated with a value; 286)
Traceback (most recent call last):
  File "/opt/airflow/dags/TransactionService/1.11.initial_Transaction_Bank.py", line 46, in transfer_data
    dest_conn, dest_cursor, source_conn, source_cursor = get_db_connection()
                                                         ^^^^^^^^^^^^^^^^^^^
  File "/opt/airflow/dags/TransactionService/1.11.initial_Transaction_Bank.py", line 28, in get_db_connection
    dest_conn = get_Report_connection()
                ^^^^^^^^^^^^^^^^^^^^^^^
  File "/opt/airflow/dags/connection.py", line 25, in get_Report_connection
    return psycopg2.connect(conn_str)
           ^^^^^^^^^^^^^^^^^^^^^^^^^^
  File "/home/airflow/.local/lib/python3.12/site-packages/psycopg2/__init__.py", line 122, in connect
    conn = _connect(dsn, connection_factory=connection_factory, **kwasync)
           ^^^^^^^^^^^^^^^^^^^^^^^^^^^^^^^^^^^^^^^^^^^^^^^^^^^^^^^^^^^^^^^
psycopg2.OperationalError: connection to server at "10.2.28.190", port 5432 failed: FATAL:  database "Report" does not exist


During handling of the above exception, another exception occurred:

Traceback (most recent call last):
  File "/home/airflow/.local/lib/python3.12/site-packages/airflow/task/task_runner/standard_task_runner.py", line 117, in _start_by_fork
    ret = args.func(args, dag=self.dag)
          ^^^^^^^^^^^^^^^^^^^^^^^^^^^^^
  File "/home/airflow/.local/lib/python3.12/site-packages/airflow/cli/cli_config.py", line 49, in command
    return func(*args, **kwargs)
           ^^^^^^^^^^^^^^^^^^^^^
  File "/home/airflow/.local/lib/python3.12/site-packages/airflow/utils/cli.py", line 116, in wrapper
    return f(*args, **kwargs)
           ^^^^^^^^^^^^^^^^^^
  File "/home/airflow/.local/lib/python3.12/site-packages/airflow/cli/commands/task_command.py", line 483, in task_run
    task_return_code = _run_task_by_selected_method(args, _dag, ti)
                       ^^^^^^^^^^^^^^^^^^^^^^^^^^^^^^^^^^^^^^^^^^^^
  File "/home/airflow/.local/lib/python3.12/site-packages/airflow/cli/commands/task_command.py", line 256, in _run_task_by_selected_method
    return _run_raw_task(args, ti)
           ^^^^^^^^^^^^^^^^^^^^^^^
  File "/home/airflow/.local/lib/python3.12/site-packages/airflow/cli/commands/task_command.py", line 341, in _run_raw_task
    return ti._run_raw_task(
           ^^^^^^^^^^^^^^^^^
  File "/home/airflow/.local/lib/python3.12/site-packages/airflow/utils/session.py", line 97, in wrapper
    return func(*args, session=session, **kwargs)
           ^^^^^^^^^^^^^^^^^^^^^^^^^^^^^^^^^^^^^^
  File "/home/airflow/.local/lib/python3.12/site-packages/airflow/models/taskinstance.py", line 3005, in _run_raw_task
    return _run_raw_task(
           ^^^^^^^^^^^^^^
  File "/home/airflow/.local/lib/python3.12/site-packages/airflow/models/taskinstance.py", line 273, in _run_raw_task
    TaskInstance._execute_task_with_callbacks(
  File "/home/airflow/.local/lib/python3.12/site-packages/airflow/models/taskinstance.py", line 3159, in _execute_task_with_callbacks
    result = self._execute_task(context, task_orig)
             ^^^^^^^^^^^^^^^^^^^^^^^^^^^^^^^^^^^^^^
  File "/home/airflow/.local/lib/python3.12/site-packages/airflow/models/taskinstance.py", line 3183, in _execute_task
    return _execute_task(self, context, task_orig)
           ^^^^^^^^^^^^^^^^^^^^^^^^^^^^^^^^^^^^^^^
  File "/home/airflow/.local/lib/python3.12/site-packages/airflow/models/taskinstance.py", line 767, in _execute_task
    result = _execute_callable(context=context, **execute_callable_kwargs)
             ^^^^^^^^^^^^^^^^^^^^^^^^^^^^^^^^^^^^^^^^^^^^^^^^^^^^^^^^^^^^^
  File "/home/airflow/.local/lib/python3.12/site-packages/airflow/models/taskinstance.py", line 733, in _execute_callable
    return ExecutionCallableRunner(
           ^^^^^^^^^^^^^^^^^^^^^^^^
  File "/home/airflow/.local/lib/python3.12/site-packages/airflow/utils/operator_helpers.py", line 252, in run
    return self.func(*args, **kwargs)
           ^^^^^^^^^^^^^^^^^^^^^^^^^^
  File "/home/airflow/.local/lib/python3.12/site-packages/airflow/models/baseoperator.py", line 422, in wrapper
    return func(self, *args, **kwargs)
           ^^^^^^^^^^^^^^^^^^^^^^^^^^^
  File "/home/airflow/.local/lib/python3.12/site-packages/airflow/operators/python.py", line 238, in execute
    return_value = self.execute_callable()
                   ^^^^^^^^^^^^^^^^^^^^^^^
  File "/home/airflow/.local/lib/python3.12/site-packages/airflow/operators/python.py", line 256, in execute_callable
    return runner.run(*self.op_args, **self.op_kwargs)
           ^^^^^^^^^^^^^^^^^^^^^^^^^^^^^^^^^^^^^^^^^^^
  File "/home/airflow/.local/lib/python3.12/site-packages/airflow/utils/operator_helpers.py", line 252, in run
    return self.func(*args, **kwargs)
           ^^^^^^^^^^^^^^^^^^^^^^^^^^
  File "/opt/airflow/dags/TransactionService/1.11.initial_Transaction_Bank.py", line 107, in transfer_data
    source_cursor.close()
    ^^^^^^^^^^^^^
UnboundLocalError: cannot access local variable 'source_cursor' where it is not associated with a value
[2025-02-10T04:56:34.376+0000] {local_task_job_runner.py:266} INFO - Task exited with return code 1
[2025-02-10T04:56:34.405+0000] {taskinstance.py:3895} INFO - 0 downstream tasks scheduled from follow-on schedule check
[2025-02-10T04:56:34.408+0000] {local_task_job_runner.py:245} INFO - ::endgroup::
